<mujoco model="aliengo_description">
    <compiler angle="radian" meshdir="./assets/" autolimits="true"/>
    <option cone="elliptic" impratio="100" />
    <size njmax="500" nconmax="100" />
    <option gravity='0 0 -9.806' timestep='0.002'/>

    <!-- <default>
        <geom contype="1" conaffinity="1" friction="0.8 0.02 0.01" rgba="0.5 0.6 0.7 1" margin="0.001" group="0"/>

        <light castshadow="false" diffuse="1 1 1"/>
        <motor ctrlrange="-44.4 44.4" ctrllimited="true"/>
        <camera fovy="60"/>
        <joint damping="3" armature="0.01" frictionloss="0.2" />
        
        
    
    </default> -->

    <default>
        <geom contype="1" conaffinity="1" friction="0.8 0.02 0.01" rgba="0.5 0.6 0.7 1" margin="0.001" group="0"/>

        <light castshadow="false" diffuse="1 1 1"/>
        <camera fovy="60"/>
        <joint damping="3" armature="0.01" frictionloss="0.2" />
        
        
        <default class="leader/visual">
            <geom type="mesh" contype="0" conaffinity="0" group="2"/>
        </default>
        <default class="leader/collision">
            <geom group="3" rgba="0.2 0.2 0.2 0.5"/>
        </default> 

        <default class="leader/hip">
            <motor ctrlrange="-44.4 44.4"/>
        </default>
        <default class="leader/thigh">
            <motor ctrlrange="-35.278 35.278"/>
        </default>
        <default class="leader/calf">
            <motor ctrlrange="-35.278 35.278"/>
        </default>

    </default>
    <!-- No rename the assests these are the mesh files-->
    <asset>
        <mesh name="leader/trunk" file="trunk.stl" />
        <mesh name="leader/hip" file="hip.stl" />
        <mesh name="leader/thigh_mirror" file="thigh_mirror.stl" />
        <mesh name="leader/calf" file="calf.stl" />
        <mesh name="leader/thigh" file="thigh.stl" />
        <mesh name="leader/base_arm_link" file="base_arm_link.stl" />
        <mesh name="leader/arm_link_1" file="arm_link_1.stl" />
        <mesh name="leader/arm_link_2" file="arm_link_2.stl" />
        <mesh name="leader/arm_link_3" file="arm_link_3.stl" />
        
    </asset>


    <!-- pos is used to set the position-->
    <worldbody>
        <light directional="true" diffuse=".8 .8 .8" pos="0 0 10" dir="0 0 -10"/>
        <camera pos="1.794 0.068 0.397" mode="trackcom" xyaxes="0.008 1.000 0.000 -0.155 0.001 0.988"/>
        <camera name="leader/track" mode="trackcom" pos="0 -1.3 1.6" xyaxes="1 0 0 0 0.707 0.707"/>
        <!-- <geom name="pallaalapa" type="sphere" size="0.05" pos="-0.8 0.5 0.1" rgba="1 0 0 1" mass="0.01"/> -->


        <body name="leader/trunk" pos="0 0 0.4">
            <inertial pos="0.00846406 0.00404455 -0.000762916" quat="-3.12625e-05 0.708321 0.00247254 0.705886" mass="13.042" diaginertia="0.174706 0.161175 0.033357" />
            <freejoint/>
            
            <!-- trunk visual mesh and collision -->
            <geom type="mesh" class="leader/visual" rgba="0.2 0.2 0.2 1" mesh="leader/trunk"/>
            <geom type="box" class="leader/collision" size="0.18 0.075 0.056"/>

            <!-- modify this to add payload -->
            <!--body name="payload" pos="0 0 0">
                <geom type="box" mass="0.01" pos="0 0 0.1" size="0.05 0.05 0.05" rgba="1 0 0 0.3"/>
            </body-->
           
            <!-- imu and camera -->
            <site name="leader/imu" pos="0 0 0"/>
            <camera name="leader/robotcam" pos="0.31 -0.005 0.00292751" quat= "0.4 0.4 -0.4 -0.4"/> 

            <!-- FL leg -->
            <body name="leader/FL_hip" pos="0.2399 0.051 0">
                <inertial pos="-0.022191 0.015144 -1.5e-05" quat="-0.0135493 0.706835 0.0117635 0.707151" mass="1.993" diaginertia="0.00558695 0.00491009 0.00290132" />
                <joint name="leader/FL_hip_joint" pos="0 0 0" axis="1 0 0" limited="true" range="-1.22173 1.22173" />
                
                <!-- FL_hip visual mesh and collision -->
                <geom type="mesh" class="leader/visual" rgba="0.2 0.2 0.2 1" mesh="leader/hip"/>
                <geom type="capsule" class="leader/collision" size="0.046 0.0209" pos="0 0.083 0" quat="0.707107 0.707107 0 0"/>
                
                <body name="leader/FL_thigh" pos="0 0.083 0">
                    <inertial pos="-0.005607 -0.003877 -0.048199" quat="0.717987 -0.031246 -0.0335669 0.694544" mass="0.639" diaginertia="0.0058474 0.00571186 0.000324584" />
                    <joint name="leader/FL_thigh_joint" pos="0 0 0" axis="0 1 0" />
                    
                    <!-- FL_thigh visual mesh and collision -->
                    <geom type="mesh" class="leader/visual" rgba="0.2 0.2 0.2 1" mesh="leader/thigh"/>
                    <geom type="box" class="leader/collision" size="0.125 0.0187 0.0215" pos="0 0 -0.125" quat="0.707107 0 0.707107 0"/>
                    
                    <body name="leader/FL_calf" pos="0 0 -0.25">
                        <inertial pos="0.00215606 4.88427e-05 -0.166671" quat="0.707462 0.00517582 0.00535172 0.706712" mass="0.267" diaginertia="0.00690975 0.00689712 5.4885e-05" />
                        <joint name="leader/FL_calf_joint" pos="0 0 0" axis="0 1 0" limited="true" range="-2.77507 -0.645772" />
                        
                        <!-- FL_calf visual mesh and collision -->
                        <geom type="mesh" class="leader/visual" rgba="0 0 0 1" mesh="leader/calf" />
                        <geom type="box" class="leader/collision" size="0.125 0.0104 0.008" pos="0 0 -0.125" quat="0.707107 0 0.707107 0"/>
                        
                        <!-- FL_foot only collision -->
                        <geom name="FL1" class="leader/collision" size="0.0265" pos="0 0 -0.25" />
                    </body>
                </body>
            </body>

            <!-- FR leg -->
            <body name="leader/FR_hip" pos="0.2399 -0.051 0">
                <inertial pos="-0.022191 -0.015144 -1.5e-05" quat="0.0135493 0.706835 -0.0117635 0.707151" mass="1.993" diaginertia="0.00558695 0.00491009 0.00290132" />
                <joint name="leader/FR_hip_joint" pos="0 0 0" axis="1 0 0" limited="true" range="-1.22173 1.22173" />
                
                <!-- FR_hip visual mesh and collision -->
                <geom type="mesh" mesh="leader/hip" class="leader/visual" quat="0 1 0 0" rgba="0.2 0.2 0.2 1"/>
                <geom type="capsule" class="leader/collision" size="0.046 0.0209" pos="0 -0.083 0" quat="0.707107 0.707107 0 0"/>
                
                <body name="leader/FR_thigh" pos="0 -0.083 0">
                    <inertial pos="-0.005607 0.003877 -0.048199" quat="0.694544 -0.0335669 -0.031246 0.717987" mass="0.639" diaginertia="0.0058474 0.00571186 0.000324584" />
                    <joint name="leader/FR_thigh_joint" pos="0 0 0" axis="0 1 0" />
                    
                    <!-- FR_thigh visual mesh and collision -->
                    <geom type="mesh" mesh="leader/thigh_mirror" class="leader/visual" rgba="0.2 0.2 0.2 1" />
                    <geom type="box" class="leader/collision" size="0.125 0.0187 0.0215" pos="0 0 -0.125" quat="0.707107 0 0.707107 0"/>
                    
                    <body name="leader/FR_calf" pos="0 0 -0.25">
                        <inertial pos="0.00215606 4.88427e-05 -0.166671" quat="0.707462 0.00517582 0.00535172 0.706712" mass="0.267" diaginertia="0.00690975 0.00689712 5.4885e-05" />
                        <joint name="leader/FR_calf_joint" pos="0 0 0" axis="0 1 0" limited="true" range="-2.77507 -0.645772" />
                        
                        <!-- FR_calf visual mesh and collision -->
                        <geom type="mesh" mesh="leader/calf" class="leader/visual" rgba="0 0 0 1"/>
                        <geom type="box" class="leader/collision" size="0.125 0.0104 0.008" pos="0 0 -0.125" quat="0.707107 0 0.707107 0"/>
                        
                        <!-- FR_foot only collision -->
                        <geom name="FR1" class="leader/collision" size="0.0265" pos="0 0 -0.25"/>
                    </body>
                </body>
            </body>
            
            <!-- RL leg -->
            <body name="leader/RL_hip" pos="-0.2399 0.051 0">
                <inertial pos="0.022191 0.015144 -1.5e-05" quat="0.0117635 0.707151 -0.0135493 0.706835" mass="1.993" diaginertia="0.00558695 0.00491009 0.00290132" />
                <joint name="leader/RL_hip_joint" pos="0 0 0" axis="1 0 0" limited="true" range="-1.22173 1.22173" />
                
                <!-- RL_hip visual mesh and collision -->
                <geom type="mesh" class="leader/visual" quat="0 0 1 0" rgba="0.2 0.2 0.2 1" mesh="leader/hip"/>
                <geom type="capsule" class="leader/collision" size="0.046 0.0209" pos="0 0.083 0" quat="0.707107 0.707107 0 0"/>
                
                <body name="leader/RL_thigh" pos="0 0.083 0">
                    <inertial pos="-0.005607 -0.003877 -0.048199" quat="0.717987 -0.031246 -0.0335669 0.694544" mass="0.639" diaginertia="0.0058474 0.00571186 0.000324584" />
                    <joint name="leader/RL_thigh_joint" pos="0 0 0" axis="0 1 0" />
                    
                    <!-- RL_thigh visual mesh and collision -->
                    <geom type="mesh" class="leader/visual" rgba="0.2 0.2 0.2 1" mesh="leader/thigh"/>
                    <geom type="box" class="leader/collision" size="0.125 0.0187 0.0215" pos="0 0 -0.125" quat="0.707107 0 0.707107 0"/>
                    
                    <body name="leader/RL_calf" pos="0 0 -0.25">
                        <inertial pos="0.00215606 4.88427e-05 -0.166671" quat="0.707462 0.00517582 0.00535172 0.706712" mass="0.267" diaginertia="0.00690975 0.00689712 5.4885e-05" />
                        <joint name="leader/RL_calf_joint" pos="0 0 0" axis="0 1 0" limited="true" range="-2.77507 -0.645772" />
                        
                        <!-- RL_calf visual mesh and collision -->
                        <geom type="mesh" class="leader/visual" rgba="0 0 0 1" mesh="leader/calf"/>
                        <geom type="box" class="leader/collision" size="0.125 0.0104 0.008" pos="0 0 -0.125" quat="0.707107 0 0.707107 0"/>
                        
                        <!-- RL_foot only collision -->
                        <geom name="RL1" class="leader/collision" size="0.0265" pos="0 0 -0.25"/>
                    </body>
                </body>
            </body>
            
            <!-- RR leg -->
            <body name="leader/RR_hip" pos="-0.2399 -0.051 0">
                <inertial pos="0.022191 -0.015144 -1.5e-05" quat="-0.0117635 0.707151 0.0135493 0.706835" mass="1.993" diaginertia="0.00558695 0.00491009 0.00290132" />
                <joint name="leader/RR_hip_joint" pos="0 0 0" axis="1 0 0" limited="true" range="-1.22173 1.22173" />
                
                <!-- RR_hip visual mesh and collision -->
                <geom type="mesh" class="leader/visual" quat="0 0 0 -1" rgba="0.2 0.2 0.2 1" mesh="leader/hip"/>
                <geom type="capsule" class="leader/collision" size="0.046 0.0209" pos="0 -0.083 0" quat="0.707107 0.707107 0 0"/>
                
                <body name="leader/RR_thigh" pos="0 -0.083 0">
                    <inertial pos="-0.005607 0.003877 -0.048199" quat="0.694544 -0.0335669 -0.031246 0.717987" mass="0.639" diaginertia="0.0058474 0.00571186 0.000324584" />
                    <joint name="leader/RR_thigh_joint" pos="0 0 0" axis="0 1 0" />
                    
                    <!-- RR_thigh visual mesh and collision -->
                    <geom type="mesh" class="leader/visual" rgba="0.2 0.2 0.2 1" mesh="leader/thigh_mirror"/>
                    <geom type="box" class="leader/collision" size="0.125 0.0187 0.0215" pos="0 0 -0.125" quat="0.707107 0 0.707107 0"/>
                    
                    <body name="leader/RR_calf" pos="0 0 -0.25">
                        <inertial pos="0.00215606 4.88427e-05 -0.166671" quat="0.707462 0.00517582 0.00535172 0.706712" mass="0.267" diaginertia="0.00690975 0.00689712 5.4885e-05" />
                        <joint name="leader/RR_calf_joint" pos="0 0 0" axis="0 1 0" limited="true" range="-2.77507 -0.645772" />
                        
                        <!-- RR_calf visual mesh and collision -->
                        <geom type="mesh" class="leader/visual" rgba="0 0 0 1" mesh="leader/calf"/>
                        <geom type="box" class="leader/collision" size="0.125 0.0104 0.008" pos="0 0 -0.125" quat="0.707107 0 0.707107 0"/>
                        
                        <!-- RR_foot only collision -->
                        <geom name="RR1" class="leader/collision" size="0.0265" pos="0 0 -0.25" rgba="0 0 0 0"/>
                    </body>
                </body>
            </body>

            <!-- LEADER CONFIGURATION -->
            <body name="leader/arm_base" pos="-0.3 0 0.056" >

                    <inertial pos="0. 0.0 0.0" quat="0 0 0 1" mass="0.02" diaginertia="0.000004622 0.000004495 0.000002079" /> 
                    <geom quat="0 0 0 1" type="mesh" contype="0" conaffinity="0" group="2" rgba="0.2 0.2 0.2 1" mesh="leader/base_arm_link" />
                    <geom size="0.0046 0.00209" pos="0 0 0" quat="0.707107 0.707107 0 0" type="capsule" rgba="0.2 0.2 0.2 0" />

                    <body name="leader/arm_link_0" pos="0 0 0.06" quat="0 0 0 1">
                        <inertial pos="0. 0 0." quat="0 0 0 1" mass="0.5" diaginertia="0.000004622 0.000004495 0.000002079" />
                        <joint name="leader/arm_link_1_joint" pos="0. 0 0." axis="0 0 1" limited="true" range="-1 1"  stiffness="10"
                        damping="1" />
                        <geom type="mesh" contype="0" conaffinity="0" group="2" rgba="0.2 0.2 0.2 1" mesh="leader/arm_link_1" />
                        
                        <body name="leader/arm_link_1" pos="0.05 0 0.035 ">
                            <inertial pos="0.0194 0.0 -0.125" quat="0 0 0 1" mass="0.5" diaginertia="0.00000457 0.000004831 0.000001409" />
                            <joint name="leader/arm_link_2_joint" pos="0.01 0 0.0" axis="0 1 0" limited="true" range="-1 1" stiffness="10"
                            damping="1" />
                            <geom type="mesh" contype="0" conaffinity="0" group="2" rgba="0.2 0.2 0.2 1" mesh="leader/arm_link_2" />
                            <geom size="0.04 0.0002 0.1" pos="0. 0 0" quat="0 0 0 1" type="capsule" rgba="0.2 0.2 0.2 0" />

                            <body name="leader/arm_link_2" pos="0.18 0.0 0.185" quat="1 0. 0 0">
                                <inertial pos="0.0388 0.0 -0.25" quat="1 0 0 0" mass="0.220" diaginertia="0.000011088 0.00001072 0.000011255" />

                                <joint name="leader/arm_link_3_joint" pos="0. 0 0" axis="0 1 0" limited="false" range="-1 0.2" stiffness="10"
                                damping="1" />
                                <geom name="leader/apply_force_frame" type="mesh" contype="0" conaffinity="0" group="2" rgba="0 0 0 1" mesh="leader/arm_link_3" />
                                <geom size="0.03 0.03 0.15" pos="0.02 0 -0.15" quat="0 0 1 1" type="box" rgba="0 0 0 0" />

                                <site name="leader/eef_leader" pos="0.04 0 -0.25" size="0.01" quat="-1 0 0 0"/>

                            
                            
                                <body name="leader/eef" pos="0.04 0 -0.25" quat="1 0 0 0">
                                    <inertial pos="0 0 0" mass="0.1" diaginertia="0.00001 0.00001 0.00001"/>
                                    <joint name="leader/eef_joint"  damping="0.1"/>
                                    <geom name="leader/eef_geom" type="sphere" size="0.02" rgba="0 1 0 1" contype="0" conaffinity="0"/>
                                    <site name="leader/eef_contact" pos="0 0 0" size="0.01" rgba="1 0 0 1"/>
                                </body>
                            </body>
                        </body> 
                    </body>
            </body>

        </body>

        <!-- add a box mounting point -->
        <!-- <body name="mountpoint" pos="-2.5 0 0.1">
            <geom type="box" size="0.1 0.1 0.1" rgba="0.8 0.8 0.8 1"/>
            <site name="mount_pooint" pos="0 0 0" size="0.01" rgba="1 0 0 1"/>
        </body> -->



    </worldbody>

    <actuator>       
        <motor name="leader/FR_hip"   class="leader/hip"    gear="1" joint="leader/FR_hip_joint"/>
        <motor name="leader/FR_thigh" class="leader/thigh"  gear="1" joint="leader/FR_thigh_joint"/>
        <motor name="leader/FR_calf"  class="leader/calf"   gear="1" joint="leader/FR_calf_joint"/>
        <motor name="leader/FL_hip"   class="leader/hip"    gear="1" joint="leader/FL_hip_joint"/>
        <motor name="leader/FL_thigh" class="leader/thigh"  gear="1" joint="leader/FL_thigh_joint"/>
        <motor name="leader/FL_calf"  class="leader/calf"   gear="1" joint="leader/FL_calf_joint"/>
        <motor name="leader/RR_hip"   class="leader/hip"    gear="1" joint="leader/RR_hip_joint"/>
        <motor name="leader/RR_thigh" class="leader/thigh"  gear="1" joint="leader/RR_thigh_joint"/>
        <motor name="leader/RR_calf"  class="leader/calf"   gear="1" joint="leader/RR_calf_joint" />
        <motor name="leader/RL_hip"   class="leader/hip"    gear="1" joint="leader/RL_hip_joint"/>
        <motor name="leader/RL_thigh" class="leader/thigh"  gear="1" joint="leader/RL_thigh_joint"/>
        <motor name="leader/RL_calf"  class="leader/calf"   gear="1" joint="leader/RL_calf_joint"/>
    </actuator>

    <sensor>
<!-- 
        <jointpos name="FR_hip_pos"     joint="FR_hip_joint"/>
        <jointpos name="FR_thigh_pos"   joint="FR_thigh_joint"/>
        <jointpos name="FR_calf_pos"    joint="FR_calf_joint"/>
        <jointpos name="FL_hip_pos"     joint="FL_hip_joint"/>
        <jointpos name="FL_thigh_pos"   joint="FL_thigh_joint"/>
        <jointpos name="FL_calf_pos"    joint="FL_calf_joint"/>
        <jointpos name="RR_hip_pos"     joint="RR_hip_joint"/>
        <jointpos name="RR_thigh_pos"   joint="RR_thigh_joint"/>
        <jointpos name="RR_calf_pos"    joint="RR_calf_joint" />
        <jointpos name="RL_hip_pos"     joint="RL_hip_joint"/>
        <jointpos name="RL_thigh_pos"   joint="RL_thigh_joint"/>
        <jointpos name="RL_calf_pos"    joint="RL_calf_joint"/>
        <jointvel name="FR_hip_vel"     joint="FR_hip_joint"/>
        <jointvel name="FR_thigh_vel"   joint="FR_thigh_joint"/>
        <jointvel name="FR_calf_vel"    joint="FR_calf_joint"/>
        <jointvel name="FL_hip_vel"     joint="FL_hip_joint"/>
        <jointvel name="FL_thigh_vel"   joint="FL_thigh_joint"/>
        <jointvel name="FL_calf_vel"    joint="FL_calf_joint"/>
        <jointvel name="RR_hip_vel"     joint="RR_hip_joint"/>
        <jointvel name="RR_thigh_vel"   joint="RR_thigh_joint"/>
        <jointvel name="RR_calf_vel"    joint="RR_calf_joint" />
        <jointvel name="RL_hip_vel"     joint="RL_hip_joint"/>
        <jointvel name="RL_thigh_vel"   joint="RL_thigh_joint"/>
        <jointvel name="RL_calf_vel"    joint="RL_calf_joint"/>

        <accelerometer name="Body_Acc" site="imu"/>

        <gyro name="Body_Gyro" site="imu"/> -->

        <jointpos name="leader/arm_link_1_joint_pos" joint="leader/arm_link_1_joint"/>
        <jointpos name="leader/arm_link_2_joint_pos" joint="leader/arm_link_2_joint"/>
        <jointpos name="leader/arm_link_3_joint_pos" joint="leader/arm_link_3_joint"/>


    </sensor>

    <!--this defines the initial position of the robot-->
    <keyframe>
        <key name="home" qpos="0. 0 0.35  1 0 0 0 
        0 0.9 -1.8 0 0.9 -1.8 0 0.9 -1.8 0 0.9 -1.8 0 0 0. 0.4
                               
                             "
        ctrl="0 0.9 -1.8 0 0.9 -1.8 0 0.9 -1.8 0 0.9 -1.8 
              "/>
    </keyframe>
</mujoco>
